- bioimageio_core_version: 0.5.7
  bioimageio_spec_version: 0.4.8
  error: '''str'' object has no attribute ''decode'''
  name: Reproduce test outputs with ilastik 1.4.0rc8 (keras_hdf5)
  source_name: 10.5281/zenodo.5817052/5850574
  status: failed
  traceback: ["  File \"/home/runner/micromamba/envs/ilastik-release/lib/python3.7/site-packages/bioimageio/core/resource_tests.py\",
      line 157, in _test_model_inference\n    bioimageio_model=model, devices=devices,
      weight_format=weight_format\n", "  File \"/home/runner/micromamba/envs/ilastik-release/lib/python3.7/site-packages/bioimageio/core/prediction_pipeline/_prediction_pipeline.py\",
      line 122, in __enter__\n    self.load()\n", "  File \"/home/runner/micromamba/envs/ilastik-release/lib/python3.7/site-packages/bioimageio/core/prediction_pipeline/_prediction_pipeline.py\",
      line 180, in load\n    self._model.load()\n", "  File \"/home/runner/micromamba/envs/ilastik-release/lib/python3.7/site-packages/bioimageio/core/prediction_pipeline/_model_adapters/_model_adapter.py\",
      line 57, in load\n    self._load(devices=devices or self.default_devices)\n",
    "  File \"/home/runner/micromamba/envs/ilastik-release/lib/python3.7/site-packages/bioimageio/core/prediction_pipeline/_model_adapters/_keras_model_adapter.py\",
      line 41, in _load\n    self._model = keras.models.load_model(weight_file)\n",
    "  File \"/home/runner/micromamba/envs/ilastik-release/lib/python3.7/site-packages/tensorflow/python/keras/saving/save.py\",
      line 146, in load_model\n    return hdf5_format.load_model_from_hdf5(filepath,
      custom_objects, compile)\n", "  File \"/home/runner/micromamba/envs/ilastik-release/lib/python3.7/site-packages/tensorflow/python/keras/saving/hdf5_format.py\",
      line 210, in load_model_from_hdf5\n    model_config = json.loads(model_config.decode('utf-8'))\n"]
  warnings:
    non-validation-warnings: ['Model tensorflow version (1, 15) does not match 1.14.0.The
        prediction results may be wrong']
- bioimageio_core_version: 0.5.7
  bioimageio_spec_version: 0.4.8
  error: '[Errno 20] Not a directory: ''/tmp/runner/bioimageio_cache/https/zenodo.org/api/records/5850574/files/tf_weights.zip/content/saved_model.pb'''
  name: Reproduce test outputs with ilastik 1.4.0rc8 (tensorflow_saved_model_bundle)
  source_name: 10.5281/zenodo.5817052/5850574
  status: failed
  traceback: ["  File \"/home/runner/micromamba/envs/ilastik-release/lib/python3.7/site-packages/bioimageio/core/resource_tests.py\",
      line 157, in _test_model_inference\n    bioimageio_model=model, devices=devices,
      weight_format=weight_format\n", "  File \"/home/runner/micromamba/envs/ilastik-release/lib/python3.7/site-packages/bioimageio/core/prediction_pipeline/_prediction_pipeline.py\",
      line 122, in __enter__\n    self.load()\n", "  File \"/home/runner/micromamba/envs/ilastik-release/lib/python3.7/site-packages/bioimageio/core/prediction_pipeline/_prediction_pipeline.py\",
      line 180, in load\n    self._model.load()\n", "  File \"/home/runner/micromamba/envs/ilastik-release/lib/python3.7/site-packages/bioimageio/core/prediction_pipeline/_model_adapters/_model_adapter.py\",
      line 57, in load\n    self._load(devices=devices or self.default_devices)\n",
    "  File \"/home/runner/micromamba/envs/ilastik-release/lib/python3.7/site-packages/bioimageio/core/prediction_pipeline/_model_adapters/_tensorflow_model_adapter.py\",
      line 65, in _load\n    weight_file = self.require_unzipped(self.bioimageio_model.weights[self.weight_format].source)\n",
    "  File \"/home/runner/micromamba/envs/ilastik-release/lib/python3.7/site-packages/bioimageio/core/prediction_pipeline/_model_adapters/_tensorflow_model_adapter.py\",
      line 25, in require_unzipped\n    f.extractall(out_path)\n", "  File \"/home/runner/micromamba/envs/ilastik-release/lib/python3.7/zipfile.py\",
      line 1636, in extractall\n    self._extract_member(zipinfo, path, pwd)\n", "  File
      \"/home/runner/micromamba/envs/ilastik-release/lib/python3.7/zipfile.py\", line
      1690, in _extract_member\n    open(targetpath, \"wb\") as target:\n"]
  warnings:
    non-validation-warnings: ['Model tensorflow version (1, 15) does not match 1.14.0.The
        prediction results may be wrong']
